Workbook
Name Combine: _CombineConfig!$A$1
Name rng_pasteID: _CombineConfig!$A$2

Sheet template
A1: Master PL Combine RPT Tool | G1: Initial Combined RPT | K1: Individual RPT's
A2: Output| RPT | K2: RPT1 | L2: RPT2 | M2: RPT3 | N2: RPT4
C3: OUTPUT VECTOR | G3: OUTPUT VECTOR | K3: INPUT VECTOR | L3: INPUT VECTOR | M3: INPUT VECTOR | N3: INPUT VECTOR
C5: Combined | G5: Combined-Initial | K5: 1 | L5: 2 | M5: 3 | N5: 4
A6: RPT Information | K6: =IF('RPT1'!$J6="","",'RPT1'!$J6) | L6: =IF('RPT2'!$J6="","",'RPT2'!$J6) | M6: =IF('RPT3'!$J6="","",'RPT3'!$J6) | N6: =IF('RPT4'!$J6="","",'RPT4'!$J6)
A7: RPT Version | K7: =IF('RPT1'!$J7="","",'RPT1'!$J7) | L7: =IF('RPT2'!$J7="","",'RPT2'!$J7) | M7: =IF('RPT3'!$J7="","",'RPT3'!$J7) | N7: =IF('RPT4'!$J7="","",'RPT4'!$J7)
A8: RPT ID | C8: =IF(Combine="Y", $G8, 0) -> RPT8336655253428HQ | G8: =rng_pasteID -> RPT8336655253428HQ | K8: =IF('RPT1'!$J8="","",'RPT1'!$J8) -> RPT8336655253428HQ | L8: =IF('RPT2'!$J8="","",'RPT2'!$J8) -> RPT7846672245493EJ | M8: =IF('RPT3'!$J8="","",'RPT3'!$J8) -> RPT2307771054698PL | N8: =IF('RPT4'!$J8="","",'RPT4'!$J8) -> RPT4790517414883UF
A9: RPT Run Date | C9: =IF(Combine="Y", $G9, 0) -> 46276.471 | G9: ='Output| Specialty RPT'!$B$5 -> 46276.471 | K9: =IF('RPT1'!$J9="","",'RPT1'!$J9) -> 2025-12-23T17:48:58.000+00:00 | L9: =IF('RPT2'!$J9="","",'RPT2'!$J9) -> 2025-12-23T17:48:58.000+00:00 | M9: =IF('RPT3'!$J9="","",'RPT3'!$J9) -> 2025-12-23T17:48:58.000+00:00 | N9: =IF('RPT4'!$J9="","",'RPT4'!$J9) -> 2025-12-23T17:48:58.000+00:00
A10: RPT Repository Location | C10: =IF(Combine="Y", $G10, 0) -> N/A | G10: =IF($K10="[blank]", "[blank]", IF(AND( IF($L10="[blank]",TRUE,$K10=$L10), IF($M10="[blank]",TRUE,$K10=$M10), IF($N10="[blank]",TRUE,$K10=$N10)), $K10, "Combined RPT")) -> N/A | K10: =IF('RPT1'!$J10="","",'RPT1'!$J10) -> N/A | L10: =IF('RPT2'!$J10="","",'RPT2'!$J10) -> N/A | M10: =IF('RPT3'!$J10="","",'RPT3'!$J10) -> N/A | N10: =IF('RPT4'!$J10="","",'RPT4'!$J10) -> N/A
A11: RPT Model Year 1 | C11: =IF(Combine="Y", $G11, 0) -> 10/26 - 09/27 | G11: =IF($K11="[blank]", "[blank]", IF(AND( IF($L11="[blank]",TRUE,$K11=$L11), IF($M11="[blank]",TRUE,$K11=$M11), IF($N11="[blank]",TRUE,$K11=$N11)), $K11, "Combined RPT")) -> 10/26 - 09/27 | K11: =IF('RPT1'!$J11="","",'RPT1'!$J11) -> 10/26 - 09/27 | L11: =IF('RPT2'!$J11="","",'RPT2'!$J11) -> 10/26 - 09/27 | M11: =IF('RPT3'!$J11="","",'RPT3'!$J11) -> 10/26 - 09/27 | N11: =IF('RPT4'!$J11="","",'RPT4'!$J11) -> 10/26 - 09/27
A12: RPT Model Year 2 | C12: =IF(Combine="Y", $G12, 0) -> 10/27 - 09/28 | G12: =IF($K12="[blank]", "[blank]", IF(AND( IF($L12="[blank]",TRUE,$K12=$L12), IF($M12="[blank]",TRUE,$K12=$M12), IF($N12="[blank]",TRUE,$K12=$N12)), $K12, "Combined RPT")) -> 10/27 - 09/28 | K12: =IF('RPT1'!$J12="","",'RPT1'!$J12) -> 10/27 - 09/28 | L12: =IF('RPT2'!$J12="","",'RPT2'!$J12) -> 10/27 - 09/28 | M12: =IF('RPT3'!$J12="","",'RPT3'!$J12) -> 10/27 - 09/28 | N12: =IF('RPT4'!$J12="","",'RPT4'!$J12) -> 10/27 - 09/28
A13: RPT Model Year 3 | C13: =IF(Combine="Y", $G13, 0) -> 10/28 - 09/29 | G13: =IF($K13="[blank]", "[blank]", IF(AND( IF($L13="[blank]",TRUE,$K13=$L13), IF($M13="[blank]",TRUE,$K13=$M13), IF($N13="[blank]",TRUE,$K13=$N13)), $K13, "Combined RPT")) -> 10/28 - 09/29 | K13: =IF('RPT1'!$J13="","",'RPT1'!$J13) -> 10/28 - 09/29 | L13: =IF('RPT2'!$J13="","",'RPT2'!$J13) -> 10/28 - 09/29 | M13: =IF('RPT3'!$J13="","",'RPT3'!$J13) -> 10/28 - 09/29 | N13: =IF('RPT4'!$J13="","",'RPT4'!$J13) -> 10/28 - 09/29
A14: RPT Model Year 4 | C14: =IF(Combine="Y", $G14, 0) -> 10/29 - 09/30 | G14: =IF($K14="[blank]", "[blank]", IF(AND( IF($L14="[blank]",TRUE,$K14=$L14), IF($M14="[blank]",TRUE,$K14=$M14), IF($N14="[blank]",TRUE,$K14=$N14)), $K14, "Combined RPT")) -> 10/29 - 09/30 | K14: =IF('RPT1'!$J14="","",'RPT1'!$J14) -> 10/29 - 09/30 | L14: =IF('RPT2'!$J14="","",'RPT2'!$J14) -> 10/29 - 09/30 | M14: =IF('RPT3'!$J14="","",'RPT3'!$J14) -> 10/29 - 09/30 | N14: =IF('RPT4'!$J14="","",'RPT4'!$J14) -> 10/29 - 09/30
A15: RPT Model Year 5 | C15: =IF(Combine="Y", $G15, 0) -> 10/30 - 09/31 | G15: =IF($K15="[blank]", "[blank]", IF(AND( IF($L15="[blank]",TRUE,$K15=$L15), IF($M15="[blank]",TRUE,$K15=$M15), IF($N15="[blank]",TRUE,$K15=$N15)), $K15, "Combined RPT")) -> 10/30 - 09/31 | K15: =IF('RPT1'!$J15="","",'RPT1'!$J15) -> 10/30 - 09/31 | L15: =IF('RPT2'!$J15="","",'RPT2'!$J15) -> 10/30 - 09/31 | M15: =IF('RPT3'!$J15="","",'RPT3'!$J15) -> 10/30 - 09/31 | N15: =IF('RPT4'!$J15="","",'RPT4'!$J15) -> 10/30 - 09/31
A16: Base Start Date | C16: =IF(Combine="Y", $G16, 0) -> 10/01/2024 | G16: =IF($K16="[blank]", "[blank]", IF(AND( IF($L16="[blank]",TRUE,$K16=$L16), IF($M16="[blank]",TRUE,$K16=$M16), IF($N16="[blank]",TRUE,$K16=$N16)), $K16, "Combined RPT")) -> 10/01/2024 | K16: =IF('RPT1'!$J16="","",'RPT1'!$J16) -> 10/01/2024 | L16: =IF('RPT2'!$J16="","",'RPT2'!$J16) -> 10/01/2024 | M16: =IF('RPT3'!$J16="","",'RPT3'!$J16) -> 10/01/2024 | N16: =IF('RPT4'!$J16="","",'RPT4'!$J16) -> 10/01/2024
A17: Base End Date | C17: =IF(Combine="Y", $G17, 0) -> 09/30/2025 | G17: =IF($K17="[blank]", "[blank]", IF(AND( IF($L17="[blank]",TRUE,$K17=$L17), IF($M17="[blank]",TRUE,$K17=$M17), IF($N17="[blank]",TRUE,$K17=$N17)), $K17, "Combined RPT")) -> 09/30/2025 | K17: =IF('RPT1'!$J17="","",'RPT1'!$J17) -> 09/30/2025 | L17: =IF('RPT2'!$J17="","",'RPT2'!$J17) -> 09/30/2025 | M17: =IF('RPT3'!$J17="","",'RPT3'!$J17) -> 09/30/2025 | N17: =IF('RPT4'!$J17="","",'RPT4'!$J17) -> 09/30/2025
A18: Client Name | C18: =IF(Combine="Y", $G18, 0) -> Health Delegates Amwins Coast College Rebate Only | G18: =IF($K18="[blank]", "[blank]", IF(AND( IF($L18="[blank]",TRUE,$K18=$L18), IF($M18="[blank]",TRUE,$K18=$M18), IF($N18="[blank]",TRUE,$K18=$N18)), $K18, "Combined RPT")) -> Health Delegates Amwins Coast College Rebate Only | K18: =IF('RPT1'!$J18="","",'RPT1'!$J18) -> Health Delegates Amwins Coast College Rebate Only | L18: =IF('RPT2'!$J18="","",'RPT2'!$J18) -> Health Delegates Amwins Coast College Rebate Only | M18: =IF('RPT3'!$J18="","",'RPT3'!$J18) -> Health Delegates Amwins Coast College Rebate Only | N18: =IF('RPT4'!$J18="","",'RPT4'!$J18) -> Health Delegates Amwins Coast College Rebate Only
A19: Line of Business | C19: =IF(Combine="Y", $G19, 0) -> Medicare D | G19: =IF($K19="[blank]", "[blank]", IF(AND( IF($L19="[blank]",TRUE,$K19=$L19), IF($M19="[blank]",TRUE,$K19=$M19), IF($N19="[blank]",TRUE,$K19=$N19)), $K19, "Combined RPT")) -> Medicare D | K19: =IF('RPT1'!$J19="","",'RPT1'!$J19) -> Medicare D | L19: =IF('RPT2'!$J19="","",'RPT2'!$J19) -> Medicare D | M19: =IF('RPT3'!$J19="","",'RPT3'!$J19) -> Medicare D | N19: =IF('RPT4'!$J19="","",'RPT4'!$J19) -> Medicare D
A20: Formulary | C20: =IF(Combine="Y", $G20, 0) -> Gold 5 Tier | G20: =IF($K20="[blank]", "[blank]", IF(AND( IF($L20="[blank]",TRUE,$K20=$L20), IF($M20="[blank]",TRUE,$K20=$M20), IF($N20="[blank]",TRUE,$K20=$N20)), $K20, "Combined RPT")) -> Gold 5 Tier | K20: =IF('RPT1'!$J20="","",'RPT1'!$J20) -> Gold 5 Tier | L20: =IF('RPT2'!$J20="","",'RPT2'!$J20) -> Gold 5 Tier | M20: =IF('RPT3'!$J20="","",'RPT3'!$J20) -> Gold 5 Tier | N20: =IF('RPT4'!$J20="","",'RPT4'!$J20) -> Gold 5 Tier
A21: Exclusions | C21: =IF(Combine="Y", $G21, 0) -> Combined RPT | G21: =IF($K21="[blank]", "[blank]", IF(AND( IF($L21="[blank]",TRUE,$K21=$L21), IF($M21="[blank]",TRUE,$K21=$M21), IF($N21="[blank]",TRUE,$K21=$N21)), $K21, "Combined RPT")) -> Combined RPT | K21: =IF('RPT1'!$J21="","",'RPT1'!$J21) -> MFP 2026 | L21: =IF('RPT2'!$J21="","",'RPT2'!$J21) | M21: =IF('RPT3'!$J21="","",'RPT3'!$J21) -> MFP 2026 & 2027 | N21: =IF('RPT4'!$J21="","",'RPT4'!$J21) -> MFP 2026 & 2027
... A51: Data Filters | C51: =IF(Combine="Y", $G51, 0) -> N/A | G51: =IF($K51="[blank]", "[blank]", IF(AND( IF($L51="[blank]",TRUE,$K51=$L51), IF($M51="[blank]",TRUE,$K51=$M51), IF($N51="[blank]",TRUE,$K51=$N51)), $K51, "Combined RPT")) -> N/A | K51: =IF('RPT1'!$J51="","",'RPT1'!$J51) -> N/A | L51: =IF('RPT2'!$J51="","",'RPT2'!$J51) -> N/A | M51: =IF('RPT3'!$J51="","",'RPT3'!$J51) -> N/A | N51: =IF('RPT4'!$J51="","",'RPT4'!$J51) -> N/A
A52: Mail 30 DS Script Distribution | C52: =IF(Combine="Y", $G52, 0) -> 0 | G52: =IF(G122=0, 0, SUMPRODUCT($K122:$N122,$K52:$N52) / G122) -> 0 | K52: =IF('RPT1'!$J52="","",'RPT1'!$J52) -> 0 | L52: =IF('RPT2'!$J52="","",'RPT2'!$J52) -> 0 | M52: =IF('RPT3'!$J52="","",'RPT3'!$J52) -> 0 | N52: =IF('RPT4'!$J52="","",'RPT4'!$J52) -> 0
A53: Mail 30 DS Rebate Distribution | C53: =IF(Combine="Y", $G53, 0) -> 0 | G53: =IF($K53="[blank]", "[blank]", IF(AND( IF($L53="[blank]",TRUE,$K53=$L53), IF($M53="[blank]",TRUE,$K53=$M53), IF($N53="[blank]",TRUE,$K53=$N53)), $K53, "Combined RPT")) -> 0 | K53: =IF('RPT1'!$J53="","",'RPT1'!$J53) -> 0 | L53: =IF('RPT2'!$J53="","",'RPT2'!$J53) -> 0 | M53: =IF('RPT3'!$J53="","",'RPT3'!$J53) -> 0 | N53: =IF('RPT4'!$J53="","",'RPT4'!$J53) -> 0
A54: B/G Selected URL | C54: =IF(Combine="Y", $G54, 0) -> https://repricingrequestform.optum.com/BGDefLookup/Override | G54: =IF($K54="[blank]", "[blank]", IF(AND( IF($L54="[blank]",TRUE,$K54=$L54), IF($M54="[blank]",TRUE,$K54=$M54), IF($N54="[blank]",TRUE,$K54=$N54)), $K54, "Combined RPT")) -> https://repricingrequestform.optum.com/BGDefLookup/Override | K54: =IF('RPT1'!$J54="","",'RPT1'!$J54) -> https://repricingrequestform.optum.com/BGDefLookup/Override | L54: =IF('RPT2'!$J54="","",'RPT2'!$J54) -> https://repricingrequestform.optum.com/BGDefLookup/Override | M54: =IF('RPT3'!$J54="","",'RPT3'!$J54) -> https://repricingrequestform.optum.com/BGDefLookup/Override | N54: =IF('RPT4'!$J54="","",'RPT4'!$J54) -> https://repricingrequestform.optum.com/BGDefLookup/Override
A55: oGLP-1 Scenario for New Coverage | C55: =IF(Combine="Y", $G55, 0) -> N/A | G55: =IF($K55="[blank]", "[blank]", IF(AND( IF($L55="[blank]",TRUE,$K55=$L55), IF($M55="[blank]",TRUE,$K55=$M55), IF($N55="[blank]",TRUE,$K55=$N55)), $K55, "Combined RPT")) -> N/A | K55: =IF('RPT1'!$J55="","",'RPT1'!$J55) -> N/A | L55: =IF('RPT2'!$J55="","",'RPT2'!$J55) -> N/A | M55: =IF('RPT3'!$J55="","",'RPT3'!$J55) -> N/A | N55: =IF('RPT4'!$J55="","",'RPT4'!$J55) -> N/A
A56: [Placeholder] | C56: =IF(Combine="Y", $G56, 0) | G56: =IF($K56="[blank]", "[blank]", IF(AND( IF($L56="[blank]",TRUE,$K56=$L56), IF($M56="[blank]",TRUE,$K56=$M56), IF($N56="[blank]",TRUE,$K56=$N56)), $K56, "Combined RPT")) | K56: =IF('RPT1'!$J56="","",'RPT1'!$J56) | L56: =IF('RPT2'!$J56="","",'RPT2'!$J56) | M56: =IF('RPT3'!$J56="","",'RPT3'!$J56) | N56: =IF('RPT4'!$J56="","",'RPT4'!$J56)
A57: [Placeholder] | C57: =IF(Combine="Y", $G57, 0) | G57: =IF($K57="[blank]", "[blank]", IF(AND( IF($L57="[blank]",TRUE,$K57=$L57), IF($M57="[blank]",TRUE,$K57=$M57), IF($N57="[blank]",TRUE,$K57=$N57)), $K57, "Combined RPT")) | K57: =IF('RPT1'!$J57="","",'RPT1'!$J57) | L57: =IF('RPT2'!$J57="","",'RPT2'!$J57) | M57: =IF('RPT3'!$J57="","",'RPT3'!$J57) | N57: =IF('RPT4'!$J57="","",'RPT4'!$J57)
A58: Specialty List | C58: =IF(Combine="Y", $G58, 0) -> Standard | G58: =IF($K58="[blank]", "[blank]", IF(AND( IF($L58="[blank]",TRUE,$K58=$L58), IF($M58="[blank]",TRUE,$K58=$M58), IF($N58="[blank]",TRUE,$K58=$N58)), $K58, "Combined RPT")) -> Standard | K58: =IF('RPT1'!$J58="","",'RPT1'!$J58) -> Standard | L58: =IF('RPT2'!$J58="","",'RPT2'!$J58) -> Standard | M58: =IF('RPT3'!$J58="","",'RPT3'!$J58) -> Standard | N58: =IF('RPT4'!$J58="","",'RPT4'!$J58) -> Standard
A59: B/G Definition | C59: =IF(Combine="Y", $G59, 0) -> Standard | G59: =IF($K59="[blank]", "[blank]", IF(AND( IF($L59="[blank]",TRUE,$K59=$L59), IF($M59="[blank]",TRUE,$K59=$M59), IF($N59="[blank]",TRUE,$K59=$N59)), $K59, "Combined RPT")) -> Standard | K59: =IF('RPT1'!$J59="","",'RPT1'!$J59) -> Standard | L59: =IF('RPT2'!$J59="","",'RPT2'!$J59) -> Standard | M59: =IF('RPT3'!$J59="","",'RPT3'!$J59) -> Standard | N59: =IF('RPT4'!$J59="","",'RPT4'!$J59) -> Standard
A60: Lift Type | C60: =IF(Combine="Y", $G60, 0) -> No oGLP-1 Rebate Lift | G60: =IF($K60="[blank]", "[blank]", IF(AND( IF($L60="[blank]",TRUE,$K60=$L60), IF($M60="[blank]",TRUE,$K60=$M60), IF($N60="[blank]",TRUE,$K60=$N60)), $K60, "Combined RPT")) -> No oGLP-1 Rebate Lift | K60: =IF('RPT1'!$J60="","",'RPT1'!$J60) -> No oGLP-1 Rebate Lift | L60: =IF('RPT2'!$J60="","",'RPT2'!$J60) -> No oGLP-1 Rebate Lift | M60: =IF('RPT3'!$J60="","",'RPT3'!$J60) -> No oGLP-1 Rebate Lift | N60: =IF('RPT4'!$J60="","",'RPT4'!$J60) -> No oGLP-1 Rebate Lift
A61: Shifting | C61: =IF(Combine="Y", $G61, 0) -> Yes | G61: =IF($K61="[blank]", "[blank]", IF(AND( IF($L61="[blank]",TRUE,$K61=$L61), IF($M61="[blank]",TRUE,$K61=$M61), IF($N61="[blank]",TRUE,$K61=$N61)), $K61, "Combined RPT")) -> Yes | K61: =IF('RPT1'!$J61="","",'RPT1'!$J61) -> Yes | L61: =IF('RPT2'!$J61="","",'RPT2'!$J61) -> Yes | M61: =IF('RPT3'!$J61="","",'RPT3'!$J61) -> Yes | N61: =IF('RPT4'!$J61="","",'RPT4'!$J61) -> Yes
A62: Patent List | C62: =IF(Combine="Y", $G62, 0) -> Standard | G62: =IF($K62="[blank]", "[blank]", IF(AND( IF($L62="[blank]",TRUE,$K62=$L62), IF($M62="[blank]",TRUE,$K62=$M62), IF($N62="[blank]",TRUE,$K62=$N62)), $K62, "Combined RPT")) -> Standard | K62: =IF('RPT1'!$J62="","",'RPT1'!$J62) -> Standard | L62: =IF('RPT2'!$J62="","",'RPT2'!$J62) -> Standard | M62: =IF('RPT3'!$J62="","",'RPT3'!$J62) -> Standard | N62: =IF('RPT4'!$J62="","",'RPT4'!$J62) -> Standard
A63: Rebate Credit | C63: =IF(Combine="Y", $G63, 0) -> Combined RPT | G63: =IF($K63="[blank]", "[blank]", IF(AND( IF($L63="[blank]",TRUE,$K63=$L63), IF($M63="[blank]",TRUE,$K63=$M63), IF($N63="[blank]",TRUE,$K63=$N63)), $K63, "Combined RPT")) -> Combined RPT | K63: =IF('RPT1'!$J63="","",'RPT1'!$J63) -> Yes | L63: =IF('RPT2'!$J63="","",'RPT2'!$J63) -> Yes | M63: =IF('RPT3'!$J63="","",'RPT3'!$J63) -> Yes | N63: =IF('RPT4'!$J63="","",'RPT4'!$J63) -> No
A64: Continuation of Therapy - Non-Specialty - Applied | C64: =IF(Combine="Y", $G64, 0) -> Yes | G64: =IF($K64="[blank]", "[blank]", IF(AND( IF($L64="[blank]",TRUE,$K64=$L64), IF($M64="[blank]",TRUE,$K64=$M64), IF($N64="[blank]",TRUE,$K64=$N64)), $K64, "Combined RPT")) -> Yes | K64: =IF('RPT1'!$J64="","",'RPT1'!$J64) -> Yes | L64: =IF('RPT2'!$J64="","",'RPT2'!$J64) -> Yes | M64: =IF('RPT3'!$J64="","",'RPT3'!$J64) -> Yes | N64: =IF('RPT4'!$J64="","",'RPT4'!$J64) -> Yes
... A77: [Placeholder] | C77: =IF(Combine="Y", $G77, 0) -> N/A | G77: =IF($K77="[blank]", "[blank]", IF(AND( IF($L77="[blank]",TRUE,$K77=$L77), IF($M77="[blank]",TRUE,$K77=$M77), IF($N77="[blank]",TRUE,$K77=$N77)), $K77, "Combined RPT")) -> N/A | K77: =IF('RPT1'!$J77="","",'RPT1'!$J77) -> N/A | L77: =IF('RPT2'!$J77="","",'RPT2'!$J77) -> N/A | M77: =IF('RPT3'!$J77="","",'RPT3'!$J77) -> N/A | N77: =IF('RPT4'!$J77="","",'RPT4'!$J77) -> N/A
A79: Projected Scripts - w/o Exclusions | K79: =IF('RPT1'!$J79="","",'RPT1'!$J79) | L79: =IF('RPT2'!$J79="","",'RPT2'!$J79) | M79: =IF('RPT3'!$J79="","",'RPT3'!$J79) | N79: =IF('RPT4'!$J79="","",'RPT4'!$J79)
A80: Projected Scripts - w/o Exclusions - Mail - Brand - Year 1 | C80: -1 | G80: -1 | K80: -1 | L80: -1 | M80: -1 | N80: -1
A81: Projected Scripts - w/o Exclusions - Mail - Brand - Year 2 | C81: =IF(Combine="Y", $G81, 0) -> 714.17213 | G81: =SUM($K81:$N81) -> 714.17213 | K81: =IF('RPT1'!$J81="","",'RPT1'!$J81) -> 166.62674 | L81: =IF('RPT2'!$J81="","",'RPT2'!$J81) -> 182.54499 | M81: =IF('RPT3'!$J81="","",'RPT3'!$J81) -> 182.45541 | N81: =IF('RPT4'!$J81="","",'RPT4'!$J81) -> 182.54499
A82: Projected Scripts - w/o Exclusions - Mail - Brand - Year 3 | C82: =IF(Combine="Y", $G82, 0) -> 692.7818 | G82: =SUM($K82:$N82) -> 692.7818 | K82: =IF('RPT1'!$J82="","",'RPT1'!$J82) -> 168.11826 | L82: =IF('RPT2'!$J82="","",'RPT2'!$J82) -> 174.91569 | M82: =IF('RPT3'!$J82="","",'RPT3'!$J82) -> 174.83216 | N82: =IF('RPT4'!$J82="","",'RPT4'!$J82) -> 174.91569
A83: Projected Scripts - w/o Exclusions - Mail - Brand - Year 4 | C83: =IF(Combine="Y", $G83, 0) -> 681.78851 | G83: =SUM($K83:$N83) -> 681.78851 | K83: =IF('RPT1'!$J83="","",'RPT1'!$J83) -> 165.80537 | L83: =IF('RPT2'!$J83="","",'RPT2'!$J83) -> 172.02847 | M83: =IF('RPT3'!$J83="","",'RPT3'!$J83) -> 171.9262 | N83: =IF('RPT4'!$J83="","",'RPT4'!$J83) -> 172.02847
...

Sheet _CombineConfig
A1: Y
A2: RPT8336655253428HQ

Sheet Output| Specialty RPT
B5: 46276.471

Sheet RPT1
J8: RPT8336655253428HQ
J9: 2025-12-23T17:48:58.000+00:00
J10: N/A
J11: 10/26 - 09/27
J12: 10/27 - 09/28
J13: 10/28 - 09/29
J14: 10/29 - 09/30
J15: 10/30 - 09/31
J16: 10/01/2024
J17: 09/30/2025
J18: Health Delegates Amwins Coast College Rebate Only
J19: Medicare D
... J51: N/A
J52: 0
J53: 0
J54: https://repricingrequestform.optum.com/BGDefLookup/Override
J55: N/A
J58: Standard
J59: Standard
J60: No oGLP-1 Rebate Lift
J61: Yes
J62: Standard
J63: Yes
J64: Yes
J65: 6
J66: Yes
J67: 3
J68: No
J69: No
J70: No
J71: No
J72: No
J73: Medicare w Humira
J74: MFP 2026 list excluded
J75: <N/A>
J76: No
J77: N/A
J80: 162.05224
J81: 166.62674
J82: 168.11826
...

Sheet RPT2
J8: RPT7846672245493EJ
J9: 2025-12-23T17:48:58.000+00:00
J10: N/A
J11: 10/26 - 09/27
J12: 10/27 - 09/28
J13: 10/28 - 09/29
J14: 10/29 - 09/30
J15: 10/30 - 09/31
J16: 10/01/2024
J17: 09/30/2025
J18: Health Delegates Amwins Coast College Rebate Only
J19: Medicare D
... J51: N/A
J52: 0
J53: 0
J54: https://repricingrequestform.optum.com/BGDefLookup/Override
J55: N/A
J58: Standard
J59: Standard
J60: No oGLP-1 Rebate Lift
J61: Yes
J62: Standard
J63: Yes
J64: Yes
J65: 6
J66: Yes
J67: 3
J68: No
J69: Yes
J70: No
J71: No
J72: No
J73: <N/A>
J74: MFP Included
J75: PTD Stelara Exclusive
J76: No
J77: N/A
J80: 187.16397
J81: 182.54499
J82: 174.91569
...

Sheet RPT3
J8: RPT2307771054698PL
J9: 2025-12-23T17:48:58.000+00:00
J10: N/A
J11: 10/26 - 09/27
J12: 10/27 - 09/28
J13: 10/28 - 09/29
J14: 10/29 - 09/30
J15: 10/30 - 09/31
J16: 10/01/2024
J17: 09/30/2025
J18: Health Delegates Amwins Coast College Rebate Only
J19: Medicare D
... J51: N/A
J52: 0
J53: 0
J54: https://repricingrequestform.optum.com/BGDefLookup/Override
J55: N/A
J58: Standard
J59: Standard
J60: No oGLP-1 Rebate Lift
J61: Yes
J62: Standard
J63: Yes
J64: Yes
J65: 6
J66: Yes
J67: 3
J68: No
J69: Yes
J70: No
J71: No
J72: No
J73: Medicare w Humira
J74: MFP 2026 & 2027 lists excluded
J75: PTD Stelara Exclusive
J76: No
J77: N/A
J80: 187.09301
J81: 182.45541
J82: 174.83216
...

Sheet RPT4
J8: RPT4790517414883UF
J9: 2025-12-23T17:48:58.000+00:00
J10: N/A
J11: 10/26 - 09/27
J12: 10/27 - 09/28
J13: 10/28 - 09/29
J14: 10/29 - 09/30
J15: 10/30 - 09/31
J16: 10/01/2024
J17: 09/30/2025
J18: Health Delegates Amwins Coast College Rebate Only
J19: Medicare D
... J51: N/A
J52: 0
J53: 0
J54: https://repricingrequestform.optum.com/BGDefLookup/Override
J55: N/A
J58: Standard
J59: Standard
J60: No oGLP-1 Rebate Lift
J61: Yes
J62: Standard
J63: No
J64: Yes
J65: 6
J66: Yes
J67: 3
J68: No
J69: Yes
J70: No
J71: No
J72: No
J73: Medicare w Humira
J74: MFP 2026 & 2027 lists excluded
J75: PTD Stelara Exclusive
J76: No
J77: N/A
J80: 187.16397
J81: 182.54499
J82: 174.91569
...
