Workbook
Name Combine: '_CombineConfig'!$A$1
Name rng_pasteID: '_CombineConfig'!$A$2

Sheet template
A1: Master PL Combine RPT Tool | G1: Initial Combined RPT | K1: Individual RPT's
A2: Output| RPT | K2: RPT1 | L2: RPT2 | M2: RPT3
C3: OUTPUT VECTOR | G3: OUTPUT VECTOR | K3: INPUT VECTOR | L3: INPUT VECTOR | M3: INPUT VECTOR
C5: Combined | G5: Combined-Initial | K5: 1 | L5: 2 | M5: 3
A6: RPT Information | K6: =IF('RPT1'!$J6="","",'RPT1'!$J6) | L6: =IF('RPT2'!$J6="","",'RPT2'!$J6) | M6: =IF('RPT3'!$J6="","",'RPT3'!$J6)
A7: RPT Version | K7: =IF('RPT1'!$J7="","",'RPT1'!$J7) | L7: =IF('RPT2'!$J7="","",'RPT2'!$J7) | M7: =IF('RPT3'!$J7="","",'RPT3'!$J7)
A8: RPT ID | C8: =IF(Combine="Y", $G8, 0) | G8: =rng_pasteID | K8: =IF('RPT1'!$J8="","",'RPT1'!$J8) | L8: =IF('RPT2'!$J8="","",'RPT2'!$J8) | M8: =IF('RPT3'!$J8="","",'RPT3'!$J8)
A9: RPT Run Date | C9: =IF(Combine="Y", $G9, 0) | G9: ='Output| Specialty RPT'!$B$5 | K9: =IF('RPT1'!$J9="","",'RPT1'!$J9) | L9: =IF('RPT2'!$J9="","",'RPT2'!$J9) | M9: =IF('RPT3'!$J9="","",'RPT3'!$J9)
A10: RPT Repository Location | C10: =IF(Combine="Y", $G10, 0) | G10: =IF($K10="[blank]", "[blank]", IF(AND( IF($L10="[blank]",TRUE,$K10=$L10), IF($M10="[blank]",TRUE,$K10=$M10)), $K10, "Combined RPT")) | K10: =IF('RPT1'!$J10="","",'RPT1'!$J10) | L10: =IF('RPT2'!$J10="","",'RPT2'!$J10) | M10: =IF('RPT3'!$J10="","",'RPT3'!$J10)
A11: RPT Model Year 1 | C11: =IF(Combine="Y", $G11, 0) | G11: =IF($K11="[blank]", "[blank]", IF(AND( IF($L11="[blank]",TRUE,$K11=$L11), IF($M11="[blank]",TRUE,$K11=$M11)), $K11, "Combined RPT")) | K11: =IF('RPT1'!$J11="","",'RPT1'!$J11) | L11: =IF('RPT2'!$J11="","",'RPT2'!$J11) | M11: =IF('RPT3'!$J11="","",'RPT3'!$J11)
A12: RPT Model Year 2 | C12: =IF(Combine="Y", $G12, 0) | G12: =IF($K12="[blank]", "[blank]", IF(AND( IF($L12="[blank]",TRUE,$K12=$L12), IF($M12="[blank]",TRUE,$K12=$M12)), $K12, "Combined RPT")) | K12: =IF('RPT1'!$J12="","",'RPT1'!$J12) | L12: =IF('RPT2'!$J12="","",'RPT2'!$J12) | M12: =IF('RPT3'!$J12="","",'RPT3'!$J12)
A13: RPT Model Year 3 | C13: =IF(Combine="Y", $G13, 0) | G13: =IF($K13="[blank]", "[blank]", IF(AND( IF($L13="[blank]",TRUE,$K13=$L13), IF($M13="[blank]",TRUE,$K13=$M13)), $K13, "Combined RPT")) | K13: =IF('RPT1'!$J13="","",'RPT1'!$J13) | L13: =IF('RPT2'!$J13="","",'RPT2'!$J13) | M13: =IF('RPT3'!$J13="","",'RPT3'!$J13)
A14: RPT Model Year 4 | C14: =IF(Combine="Y", $G14, 0) | G14: =IF($K14="[blank]", "[blank]", IF(AND( IF($L14="[blank]",TRUE,$K14=$L14), IF($M14="[blank]",TRUE,$K14=$M14)), $K14, "Combined RPT")) | K14: =IF('RPT1'!$J14="","",'RPT1'!$J14) | L14: =IF('RPT2'!$J14="","",'RPT2'!$J14) | M14: =IF('RPT3'!$J14="","",'RPT3'!$J14)
A15: RPT Model Year 5 | C15: =IF(Combine="Y", $G15, 0) | G15: =IF($K15="[blank]", "[blank]", IF(AND( IF($L15="[blank]",TRUE,$K15=$L15), IF($M15="[blank]",TRUE,$K15=$M15)), $K15, "Combined RPT")) | K15: =IF('RPT1'!$J15="","",'RPT1'!$J15) | L15: =IF('RPT2'!$J15="","",'RPT2'!$J15) | M15: =IF('RPT3'!$J15="","",'RPT3'!$J15)
A16: Base Start Date | C16: =IF(Combine="Y", $G16, 0) | G16: =IF($K16="[blank]", "[blank]", IF(AND( IF($L16="[blank]",TRUE,$K16=$L16), IF($M16="[blank]",TRUE,$K16=$M16)), $K16, "Combined RPT")) | K16: =IF('RPT1'!$J16="","",'RPT1'!$J16) | L16: =IF('RPT2'!$J16="","",'RPT2'!$J16) | M16: =IF('RPT3'!$J16="","",'RPT3'!$J16)
A17: Base End Date | C17: =IF(Combine="Y", $G17, 0) | G17: =IF($K17="[blank]", "[blank]", IF(AND( IF($L17="[blank]",TRUE,$K17=$L17), IF($M17="[blank]",TRUE,$K17=$M17)), $K17, "Combined RPT")) | K17: =IF('RPT1'!$J17="","",'RPT1'!$J17) | L17: =IF('RPT2'!$J17="","",'RPT2'!$J17) | M17: =IF('RPT3'!$J17="","",'RPT3'!$J17)
A18: Client Name | C18: =IF(Combine="Y", $G18, 0) | G18: =IF($K18="[blank]", "[blank]", IF(AND( IF($L18="[blank]",TRUE,$K18=$L18), IF($M18="[blank]",TRUE,$K18=$M18)), $K18, "Combined RPT")) | K18: =IF('RPT1'!$J18="","",'RPT1'!$J18) | L18: =IF('RPT2'!$J18="","",'RPT2'!$J18) | M18: =IF('RPT3'!$J18="","",'RPT3'!$J18)
A19: Line of Business | C19: =IF(Combine="Y", $G19, 0) | G19: =IF($K19="[blank]", "[blank]", IF(AND( IF($L19="[blank]",TRUE,$K19=$L19), IF($M19="[blank]",TRUE,$K19=$M19)), $K19, "Combined RPT")) | K19: =IF('RPT1'!$J19="","",'RPT1'!$J19) | L19: =IF('RPT2'!$J19="","",'RPT2'!$J19) | M19: =IF('RPT3'!$J19="","",'RPT3'!$J19)
A20: Formulary | C20: =IF(Combine="Y", $G20, 0) | G20: =IF($K20="[blank]", "[blank]", IF(AND( IF($L20="[blank]",TRUE,$K20=$L20), IF($M20="[blank]",TRUE,$K20=$M20)), $K20, "Combined RPT")) | K20: =IF('RPT1'!$J20="","",'RPT1'!$J20) | L20: =IF('RPT2'!$J20="","",'RPT2'!$J20) | M20: =IF('RPT3'!$J20="","",'RPT3'!$J20)
A21: Exclusions | C21: =IF(Combine="Y", $G21, 0) | G21: =IF($K21="[blank]", "[blank]", IF(AND( IF($L21="[blank]",TRUE,$K21=$L21), IF($M21="[blank]",TRUE,$K21=$M21)), $K21, "Combined RPT")) | K21: =IF('RPT1'!$J21="","",'RPT1'!$J21) | L21: =IF('RPT2'!$J21="","",'RPT2'!$J21) | M21: =IF('RPT3'!$J21="","",'RPT3'!$J21)
... A51: Data Filters | C51: =IF(Combine="Y", $G51, 0) | G51: =IF($K51="[blank]", "[blank]", IF(AND( IF($L51="[blank]",TRUE,$K51=$L51), IF($M51="[blank]",TRUE,$K51=$M51)), $K51, "Combined RPT")) | K51: =IF('RPT1'!$J51="","",'RPT1'!$J51) | L51: =IF('RPT2'!$J51="","",'RPT2'!$J51) | M51: =IF('RPT3'!$J51="","",'RPT3'!$J51)
A52: Mail 30 DS Script Distribution | C52: =IF(Combine="Y", $G52, 0) | G52: =IF(G122=0, 0, SUMPRODUCT($K122:$M122,$K52:$M52) / G122) | K52: =IF('RPT1'!$J52="","",'RPT1'!$J52) | L52: =IF('RPT2'!$J52="","",'RPT2'!$J52) | M52: =IF('RPT3'!$J52="","",'RPT3'!$J52)
A53: Mail 30 DS Rebate Distribution | C53: =IF(Combine="Y", $G53, 0) | G53: =IF($K53="[blank]", "[blank]", IF(AND( IF($L53="[blank]",TRUE,$K53=$L53), IF($M53="[blank]",TRUE,$K53=$M53)), $K53, "Combined RPT")) | K53: =IF('RPT1'!$J53="","",'RPT1'!$J53) | L53: =IF('RPT2'!$J53="","",'RPT2'!$J53) | M53: =IF('RPT3'!$J53="","",'RPT3'!$J53)
A54: B/G Selected URL | C54: =IF(Combine="Y", $G54, 0) | G54: =IF($K54="[blank]", "[blank]", IF(AND( IF($L54="[blank]",TRUE,$K54=$L54), IF($M54="[blank]",TRUE,$K54=$M54)), $K54, "Combined RPT")) | K54: =IF('RPT1'!$J54="","",'RPT1'!$J54) | L54: =IF('RPT2'!$J54="","",'RPT2'!$J54) | M54: =IF('RPT3'!$J54="","",'RPT3'!$J54)
A55: oGLP-1 Scenario for New Coverage | C55: =IF(Combine="Y", $G55, 0) | G55: =IF($K55="[blank]", "[blank]", IF(AND( IF($L55="[blank]",TRUE,$K55=$L55), IF($M55="[blank]",TRUE,$K55=$M55)), $K55, "Combined RPT")) | K55: =IF('RPT1'!$J55="","",'RPT1'!$J55) | L55: =IF('RPT2'!$J55="","",'RPT2'!$J55) | M55: =IF('RPT3'!$J55="","",'RPT3'!$J55)
A56: [Placeholder] | C56: =IF(Combine="Y", $G56, 0) | G56: =IF($K56="[blank]", "[blank]", IF(AND( IF($L56="[blank]",TRUE,$K56=$L56), IF($M56="[blank]",TRUE,$K56=$M56)), $K56, "Combined RPT")) | K56: =IF('RPT1'!$J56="","",'RPT1'!$J56) | L56: =IF('RPT2'!$J56="","",'RPT2'!$J56) | M56: =IF('RPT3'!$J56="","",'RPT3'!$J56)
A57: [Placeholder] | C57: =IF(Combine="Y", $G57, 0) | G57: =IF($K57="[blank]", "[blank]", IF(AND( IF($L57="[blank]",TRUE,$K57=$L57), IF($M57="[blank]",TRUE,$K57=$M57)), $K57, "Combined RPT")) | K57: =IF('RPT1'!$J57="","",'RPT1'!$J57) | L57: =IF('RPT2'!$J57="","",'RPT2'!$J57) | M57: =IF('RPT3'!$J57="","",'RPT3'!$J57)
A58: Specialty List | C58: =IF(Combine="Y", $G58, 0) | G58: =IF($K58="[blank]", "[blank]", IF(AND( IF($L58="[blank]",TRUE,$K58=$L58), IF($M58="[blank]",TRUE,$K58=$M58)), $K58, "Combined RPT")) | K58: =IF('RPT1'!$J58="","",'RPT1'!$J58) | L58: =IF('RPT2'!$J58="","",'RPT2'!$J58) | M58: =IF('RPT3'!$J58="","",'RPT3'!$J58)
A59: B/G Definition | C59: =IF(Combine="Y", $G59, 0) | G59: =IF($K59="[blank]", "[blank]", IF(AND( IF($L59="[blank]",TRUE,$K59=$L59), IF($M59="[blank]",TRUE,$K59=$M59)), $K59, "Combined RPT")) | K59: =IF('RPT1'!$J59="","",'RPT1'!$J59) | L59: =IF('RPT2'!$J59="","",'RPT2'!$J59) | M59: =IF('RPT3'!$J59="","",'RPT3'!$J59)
A60: Lift Type | C60: =IF(Combine="Y", $G60, 0) | G60: =IF($K60="[blank]", "[blank]", IF(AND( IF($L60="[blank]",TRUE,$K60=$L60), IF($M60="[blank]",TRUE,$K60=$M60)), $K60, "Combined RPT")) | K60: =IF('RPT1'!$J60="","",'RPT1'!$J60) | L60: =IF('RPT2'!$J60="","",'RPT2'!$J60) | M60: =IF('RPT3'!$J60="","",'RPT3'!$J60)
A61: Shifting | C61: =IF(Combine="Y", $G61, 0) | G61: =IF($K61="[blank]", "[blank]", IF(AND( IF($L61="[blank]",TRUE,$K61=$L61), IF($M61="[blank]",TRUE,$K61=$M61)), $K61, "Combined RPT")) | K61: =IF('RPT1'!$J61="","",'RPT1'!$J61) | L61: =IF('RPT2'!$J61="","",'RPT2'!$J61) | M61: =IF('RPT3'!$J61="","",'RPT3'!$J61)
A62: Patent List | C62: =IF(Combine="Y", $G62, 0) | G62: =IF($K62="[blank]", "[blank]", IF(AND( IF($L62="[blank]",TRUE,$K62=$L62), IF($M62="[blank]",TRUE,$K62=$M62)), $K62, "Combined RPT")) | K62: =IF('RPT1'!$J62="","",'RPT1'!$J62) | L62: =IF('RPT2'!$J62="","",'RPT2'!$J62) | M62: =IF('RPT3'!$J62="","",'RPT3'!$J62)
A63: Rebate Credit | C63: =IF(Combine="Y", $G63, 0) | G63: =IF($K63="[blank]", "[blank]", IF(AND( IF($L63="[blank]",TRUE,$K63=$L63), IF($M63="[blank]",TRUE,$K63=$M63)), $K63, "Combined RPT")) | K63: =IF('RPT1'!$J63="","",'RPT1'!$J63) | L63: =IF('RPT2'!$J63="","",'RPT2'!$J63) | M63: =IF('RPT3'!$J63="","",'RPT3'!$J63)
A64: Continuation of Therapy - Non-Specialty - Applied | C64: =IF(Combine="Y", $G64, 0) | G64: =IF($K64="[blank]", "[blank]", IF(AND( IF($L64="[blank]",TRUE,$K64=$L64), IF($M64="[blank]",TRUE,$K64=$M64)), $K64, "Combined RPT")) | K64: =IF('RPT1'!$J64="","",'RPT1'!$J64) | L64: =IF('RPT2'!$J64="","",'RPT2'!$J64) | M64: =IF('RPT3'!$J64="","",'RPT3'!$J64)
... A77: [Placeholder] | C77: =IF(Combine="Y", $G77, 0) | G77: =IF($K77="[blank]", "[blank]", IF(AND( IF($L77="[blank]",TRUE,$K77=$L77), IF($M77="[blank]",TRUE,$K77=$M77)), $K77, "Combined RPT")) | K77: =IF('RPT1'!$J77="","",'RPT1'!$J77) | L77: =IF('RPT2'!$J77="","",'RPT2'!$J77) | M77: =IF('RPT3'!$J77="","",'RPT3'!$J77)
A79: Projected Scripts - w/o Exclusions | K79: =IF('RPT1'!$J79="","",'RPT1'!$J79) | L79: =IF('RPT2'!$J79="","",'RPT2'!$J79) | M79: =IF('RPT3'!$J79="","",'RPT3'!$J79)
A80: Projected Scripts - w/o Exclusions - Mail - Brand - Year 1 | C80: =IF(Combine="Y", $G80, 0) | G80: =SUM($K80:$M80) | K80: =IF('RPT1'!$J80="","",'RPT1'!$J80) | L80: =IF('RPT2'!$J80="","",'RPT2'!$J80) | M80: =IF('RPT3'!$J80="","",'RPT3'!$J80)
A81: Projected Scripts - w/o Exclusions - Mail - Brand - Year 2 | C81: =IF(Combine="Y", $G81, 0) | G81: =SUM($K81:$M81) | K81: =IF('RPT1'!$J81="","",'RPT1'!$J81) | L81: =IF('RPT2'!$J81="","",'RPT2'!$J81) | M81: =IF('RPT3'!$J81="","",'RPT3'!$J81)
A82: Projected Scripts - w/o Exclusions - Mail - Brand - Year 3 | C82: =IF(Combine="Y", $G82, 0) | G82: =SUM($K82:$M82) | K82: =IF('RPT1'!$J82="","",'RPT1'!$J82) | L82: =IF('RPT2'!$J82="","",'RPT2'!$J82) | M82: =IF('RPT3'!$J82="","",'RPT3'!$J82)
A83: Projected Scripts - w/o Exclusions - Mail - Brand - Year 4 | C83: =IF(Combine="Y", $G83, 0) | G83: =SUM($K83:$M83) | K83: =IF('RPT1'!$J83="","",'RPT1'!$J83) | L83: =IF('RPT2'!$J83="","",'RPT2'!$J83) | M83: =IF('RPT3'!$J83="","",'RPT3'!$J83)
...

Sheet _CombineConfig
A1: Y
A2: RPT3504944005661WP

Sheet Output| Specialty RPT
B5: 46276.233

Sheet RPT1
J8: RPT3504944005661WP
J9: 2026-01-27T08:39:54.000+00:00
J10: N/A
J11: 2027
J12: 2028
J13: 2029
J14: 2030
J15: 2031
J16: 01/01/2025
J17: 11/30/2025
J18: RxAdvance HTA Groups Rebate1 - M003
J19: Medicare D
J20: Gold 5 Tier-GOV
J22: Include
J23: Include
J24: Include
J25: Include
J26: Include
J27: Include
J28: Include
... J51: N/A
J52: 0.099279515
J53: 0.07665484
J54: https://repricingrequestform.optum.com/BGDefLookup/Override
J55: N/A
J58: Standard
J59: Standard
J60: No oGLP-1 Rebate Lift
J61: No
J62: Standard
J63: Yes
J64: No
J65: 0
J66: No
J67: 0
J68: Yes
J69: Yes
J70: No
J71: No
J72: No
...

Sheet RPT2
J8: RPT7016379876729NN
J9: 2026-01-27T08:39:54.000+00:00
J10: N/A
J11: 2027
J12: 2028
J13: 2029
J14: 2030
J15: 2031
J16: 01/01/2025
J17: 11/30/2025
J18: RxAdvance HTA Groups Rebate1 - M003
J19: Medicare D
J20: Gold 5 Tier-GOV
J21: MFP 2026 & 2027
J22: Include
J23: Include
J24: Include
J25: Include
J26: Include
J27: Include
... J51: N/A
J52: 0.16376938
J53: 0.12423121
J54: https://repricingrequestform.optum.com/BGDefLookup/Override
J55: N/A
J58: Standard
J59: Standard
J60: No oGLP-1 Rebate Lift
J61: Yes
J62: Standard
J63: Yes
J64: No
J65: 0
J66: No
J67: 0
J68: Yes
J69: Yes
J70: No
J71: No
J72: No
...

Sheet RPT3
J8: RPT1161653296037EO
J9: 2026-01-27T08:39:54.000+00:00
J10: N/A
J11: 2027
J12: 2028
J13: 2029
J14: 2030
J15: 2031
J16: 01/01/2025
J17: 11/30/2025
J18: RxAdvance HTA Groups Rebate1 - M003
J19: Medicare D
J20: Gold 5 Tier-GOV
J21: nonRebatable, MFP 2026 & 2027
J22: Include
J23: Include
J24: Include
J25: Include
J26: Include
J27: Include
... J51: N/A
J52: 0.099279515
J53: 0.12423121
J54: https://repricingrequestform.optum.com/BGDefLookup/Override
J55: N/A
J58: Standard
J59: Standard
J60: No oGLP-1 Rebate Lift
J61: Yes
J62: Standard
J63: Yes
J64: No
J65: 0
J66: Yes
J67: 3
J68: Yes
J69: Yes
J70: No
J71: No
J72: No
...
